Workbook
Name Slicer_Color_B_W: #N/A
Name Slicer_Country: #N/A
Name Slicer_Genre: #N/A
Name Slicer_Recommended_Movie: #N/A
Name Slicer_Release_Year: #N/A

Sheet imdb
A1: Title | B1: Release Date | C1: Color/B&W | D1: Genre | E1: Language | F1: Country | G1: Rating | H1: Lead Actor | I1: Director Name | J1: Lead Actor FB Likes | K1: Cast FB Likes | L1: Director FB Likes | M1: Movie FB Likes | N1: IMDb Score (1-10) | O1: Total Reviews | P1: Duration (min) | Q1: Gross Revenue | R1: Budget | S1: Profit | T1: ROI(%) | U1: Success Score | V1: Release Year | W1: Release Month | X1: Director Name(Clean) | Y1: Movie Title(UPPER) | Z1: Performance Status | AA1: Genre Category | AB1: Recommended Movie | AC1: Audience Buzz Mismatch
A2: Avatar | B2: 39950 | C2: Color | D2: Action | E2: English | F2: USA | G2: PG-13 | H2: CCH Pounder | I2: James Cameron | J2: 1000 | K2: 4834 | L2: 0 | M2: 33000 | N2: 7.9 | O2: 723 | P2: 178 | Q2: 760505847 | R2: 237000000 | S2: =Q2-R2 -> 523505847 | T2: =IF(R2>0, (Q2-R2)/R2, 0) -> 2.2088854 | U2: =(N2*4) + (T2*0.4) + (M2/10000) -> 35.783554 | V2: =YEAR(B2) -> 2009 | W2: =TEXT(B2, "mmmm") -> may | X2: =TRIM(I2) -> James Cameron | Y2: =UPPER(A2) -> AVATAR | Z2: =IF(AND(R2>50000000, S2<0), "Underperformer", IF(AND(R2<10000000, S2>50000000), "Overperformer", "Normal")) -> Normal | AA2: =VLOOKUP(D2, lookups!$A$2:$B$18, 2, FALSE) -> High Budget | AB2: =IF(AND(N2>7, T2>1, U2>70), "Recommended", "Not Recommended") -> Not Recommended | AC2: =IF(N2>=8, "High Buzz / High Score", IF(AND(N2<6, T2<1), "High Buzz Mismatch", "Normal")) -> Normal
A3: Titanic | B3: 35500 | C3: Color | D3: Drama | E3: English | F3: USA | G3: PG-13 | H3: Leonardo DiCaprio | I3: James Cameron | J3: 29000 | K3: 45223 | L3: 0 | M3: 26000 | N3: 7.7 | O3: 315 | P3: 194 | Q3: 658672302 | R3: 200000000 | S3: =Q3-R3 -> 458672302 | T3: =IF(R3>0, (Q3-R3)/R3, 0) -> 2.2933615 | U3: =(N3*4) + (T3*0.4) + (M3/10000) -> 34.317345 | V3: =YEAR(B3) -> 1997 | W3: =TEXT(B3, "mmmm") -> mart | X3: =TRIM(I3) -> James Cameron | Y3: =UPPER(A3) -> TİTANİC | Z3: =IF(AND(R3>50000000, S3<0), "Underperformer", IF(AND(R3<10000000, S3>50000000), "Overperformer", "Normal")) -> Normal | AA3: =VLOOKUP(D3, lookups!$A$2:$B$18, 2, FALSE) -> Medium Budget | AB3: =IF(AND(N3>7, T3>1, U3>70), "Recommended", "Not Recommended") -> Not Recommended | AC3: =IF(N3>=8, "High Buzz / High Score", IF(AND(N3<6, T3<1), "High Buzz Mismatch", "Normal")) -> Normal
A4: Jurassic World | B4: 42188 | C4: Color | D4: Action | E4: English | F4: USA | G4: PG-13 | H4: Bryce Dallas Howard | I4: Colin Trevorrow | J4: 3000 | K4: 8458 | L4: 365 | M4: 150000 | N4: 7 | O4: 644 | P4: 124 | Q4: 652177271 | R4: 150000000 | S4: =Q4-R4 -> 502177271 | T4: =IF(R4>0, (Q4-R4)/R4, 0) -> 3.3478485 | U4: =(N4*4) + (T4*0.4) + (M4/10000) -> 44.339139 | V4: =YEAR(B4) -> 2015 | W4: =TEXT(B4, "mmmm") -> iyul | X4: =TRIM(I4) -> Colin Trevorrow | Y4: =UPPER(A4) -> JURASSİC WORLD | Z4: =IF(AND(R4>50000000, S4<0), "Underperformer", IF(AND(R4<10000000, S4>50000000), "Overperformer", "Normal")) -> Normal | AA4: =VLOOKUP(D4, lookups!$A$2:$B$18, 2, FALSE) -> High Budget | AB4: =IF(AND(N4>7, T4>1, U4>70), "Recommended", "Not Recommended") -> Not Recommended | AC4: =IF(N4>=8, "High Buzz / High Score", IF(AND(N4<6, T4<1), "High Buzz Mismatch", "Normal")) -> Normal
A5: The Avengers | B5: 41118 | C5: Color | D5: Action | E5: English | F5: USA | G5: PG-13 | H5: Chris Hemsworth | I5: Joss Whedon | J5: 26000 | K5: 87697 | L5: 0 | M5: 123000 | N5: 8.1 | O5: 703 | P5: 173 | Q5: 623279547 | R5: 220000000 | S5: =Q5-R5 -> 403279547 | T5: =IF(R5>0, (Q5-R5)/R5, 0) -> 1.8330888 | U5: =(N5*4) + (T5*0.4) + (M5/10000) -> 45.433236 | V5: =YEAR(B5) -> 2012 | W5: =TEXT(B5, "mmmm") -> iyul | X5: =TRIM(I5) -> Joss Whedon | Y5: =UPPER(A5) -> THE AVENGERS | Z5: =IF(AND(R5>50000000, S5<0), "Underperformer", IF(AND(R5<10000000, S5>50000000), "Overperformer", "Normal")) -> Normal | AA5: =VLOOKUP(D5, lookups!$A$2:$B$18, 2, FALSE) -> High Budget | AB5: =IF(AND(N5>7, T5>1, U5>70), "Recommended", "Not Recommended") -> Not Recommended | AC5: =IF(N5>=8, "High Buzz / High Score", IF(AND(N5<6, T5<1), "High Buzz Mismatch", "Normal")) -> High Buzz / High Score
A6: The Dark Knight | B6: 39577 | C6: Color | D6: Action | E6: English | F6: USA | G6: PG-13 | H6: Christian Bale | I6: Christopher Nolan | J6: 23000 | K6: 57802 | L6: 22000 | M6: 37000 | N6: 9 | O6: 645 | P6: 152 | Q6: 533316061 | R6: 185000000 | S6: =Q6-R6 -> 348316061 | T6: =IF(R6>0, (Q6-R6)/R6, 0) -> 1.8827895 | U6: =(N6*4) + (T6*0.4) + (M6/10000) -> 40.453116 | V6: =YEAR(B6) -> 2008 | W6: =TEXT(B6, "mmmm") -> may | X6: =TRIM(I6) -> Christopher Nolan | Y6: =UPPER(A6) -> THE DARK KNİGHT | Z6: =IF(AND(R6>50000000, S6<0), "Underperformer", IF(AND(R6<10000000, S6>50000000), "Overperformer", "Normal")) -> Normal | AA6: =VLOOKUP(D6, lookups!$A$2:$B$18, 2, FALSE) -> High Budget | AB6: =IF(AND(N6>7, T6>1, U6>70), "Recommended", "Not Recommended") -> Not Recommended | AC6: =IF(N6>=8, "High Buzz / High Score", IF(AND(N6<6, T6<1), "High Buzz Mismatch", "Normal")) -> High Buzz / High Score
A7: Star Wars: Episode I - The Phantom Menace | B7: 36330 | C7: Color | D7: Action | E7: English | F7: USA | G7: PG | H7: Natalie Portman | I7: George Lucas | J7: 20000 | K7: 37723 | L7: 0 | M7: 13000 | N7: 6.5 | O7: 320 | P7: 136 | Q7: 474544677 | R7: 115000000 | S7: =Q7-R7 -> 359544677 | T7: =IF(R7>0, (Q7-R7)/R7, 0) -> 3.1264755 | U7: =(N7*4) + (T7*0.4) + (M7/10000) -> 28.55059 | V7: =YEAR(B7) -> 1999 | W7: =TEXT(B7, "mmmm") -> iyun | X7: =TRIM(I7) -> George Lucas | Y7: =UPPER(A7) -> STAR WARS: EPİSODE I - THE PHANTOM MENACE | Z7: =IF(AND(R7>50000000, S7<0), "Underperformer", IF(AND(R7<10000000, S7>50000000), "Overperformer", "Normal")) -> Normal | AA7: =VLOOKUP(D7, lookups!$A$2:$B$18, 2, FALSE) -> High Budget | AB7: =IF(AND(N7>7, T7>1, U7>70), "Recommended", "Not Recommended") -> Not Recommended | AC7: =IF(N7>=8, "High Buzz / High Score", IF(AND(N7<6, T7<1), "High Buzz Mismatch", "Normal")) -> Normal
A8: Star Wars: Episode IV - A New Hope | B8: 28163 | C8: Color | D8: Action | E8: English | F8: USA | G8: PG | H8: Harrison Ford | I8: George Lucas | J8: 11000 | K8: 13485 | L8: 0 | M8: 33000 | N8: 8.7 | O8: 282 | P8: 125 | Q8: 460935665 | R8: 11000000 | S8: =Q8-R8 -> 449935665 | T8: =IF(R8>0, (Q8-R8)/R8, 0) -> 40.903242 | U8: =(N8*4) + (T8*0.4) + (M8/10000) -> 54.461297 | V8: =YEAR(B8) -> 1977 | W8: =TEXT(B8, "mmmm") -> fevral | X8: =TRIM(I8) -> George Lucas | Y8: =UPPER(A8) -> STAR WARS: EPİSODE IV - A NEW HOPE | Z8: =IF(AND(R8>50000000, S8<0), "Underperformer", IF(AND(R8<10000000, S8>50000000), "Overperformer", "Normal")) -> Normal | AA8: =VLOOKUP(D8, lookups!$A$2:$B$18, 2, FALSE) -> High Budget | AB8: =IF(AND(N8>7, T8>1, U8>70), "Recommended", "Not Recommended") -> Not Recommended | AC8: =IF(N8>=8, "High Buzz / High Score", IF(AND(N8<6, T8<1), "High Buzz Mismatch", "Normal")) -> High Buzz / High Score
A9: Avengers: Age of Ultron | B9: 42055 | C9: Color | D9: Action | E9: English | F9: USA | G9: PG-13 | H9: Chris Hemsworth | I9: Joss Whedon | J9: 26000 | K9: 92000 | L9: 0 | M9: 118000 | N9: 7.5 | O9: 635 | P9: 141 | Q9: 458991599 | R9: 250000000 | S9: =Q9-R9 -> 208991599 | T9: =IF(R9>0, (Q9-R9)/R9, 0) -> 0.8359664 | U9: =(N9*4) + (T9*0.4) + (M9/10000) -> 42.134387 | V9: =YEAR(B9) -> 2015 | W9: =TEXT(B9, "mmmm") -> fevral | X9: =TRIM(I9) -> Joss Whedon | Y9: =UPPER(A9) -> AVENGERS: AGE OF ULTRON | Z9: =IF(AND(R9>50000000, S9<0), "Underperformer", IF(AND(R9<10000000, S9>50000000), "Overperformer", "Normal")) -> Normal | AA9: =VLOOKUP(D9, lookups!$A$2:$B$18, 2, FALSE) -> High Budget | AB9: =IF(AND(N9>7, T9>1, U9>70), "Recommended", "Not Recommended") -> Not Recommended | AC9: =IF(N9>=8, "High Buzz / High Score", IF(AND(N9<6, T9<1), "High Buzz Mismatch", "Normal")) -> Normal
A10: The Dark Knight Rises | B10: 41108 | C10: Color | D10: Action | E10: English | F10: USA | G10: PG-13 | H10: Tom Hardy | I10: Christopher Nolan | J10: 27000 | K10: 106759 | L10: 22000 | M10: 164000 | N10: 8.4 | O10: 813 | P10: 164 | Q10: 448130642 | R10: 250000000 | S10: =Q10-R10 -> 198130642 | T10: =IF(R10>0, (Q10-R10)/R10, 0) -> 0.79252257 | U10: =(N10*4) + (T10*0.4) + (M10/10000) -> 50.317009 | V10: =YEAR(B10) -> 2012 | W10: =TEXT(B10, "mmmm") -> iyul | X10: =TRIM(I10) -> Christopher Nolan | Y10: =UPPER(A10) -> THE DARK KNİGHT RİSES | Z10: =IF(AND(R10>50000000, S10<0), "Underperformer", IF(AND(R10<10000000, S10>50000000), "Overperformer", "Normal")) -> Normal | AA10: =VLOOKUP(D10, lookups!$A$2:$B$18, 2, FALSE) -> High Budget | AB10: =IF(AND(N10>7, T10>1, U10>70), "Recommended", "Not Recommended") -> Not Recommended | AC10: =IF(N10>=8, "High Buzz / High Score", IF(AND(N10<6, T10<1), "High Buzz Mismatch", "Normal")) -> High Buzz / High Score
A11: Shrek 2 | B11: 38076 | C11: Color | D11: Adventure | E11: English | F11: USA | G11: PG | H11: Rupert Everett | I11: Andrew Adamson | J11: 692 | K11: 1148 | L11: 80 | M11: 0 | N11: 7.2 | O11: 205 | P11: 93 | Q11: 436471036 | R11: 150000000 | S11: =Q11-R11 -> 286471036 | T11: =IF(R11>0, (Q11-R11)/R11, 0) -> 1.9098069 | U11: =(N11*4) + (T11*0.4) + (M11/10000) -> 29.563923 | V11: =YEAR(B11) -> 2004 | W11: =TEXT(B11, "mmmm") -> mart | X11: =TRIM(I11) -> Andrew Adamson | Y11: =UPPER(A11) -> SHREK 2 | Z11: =IF(AND(R11>50000000, S11<0), "Underperformer", IF(AND(R11<10000000, S11>50000000), "Overperformer", "Normal")) -> Normal | AA11: =VLOOKUP(D11, lookups!$A$2:$B$18, 2, FALSE) -> High Budget | AB11: =IF(AND(N11>7, T11>1, U11>70), "Recommended", "Not Recommended") -> Not Recommended | AC11: =IF(N11>=8, "High Buzz / High Score", IF(AND(N11<6, T11<1), "High Buzz Mismatch", "Normal")) -> Normal
A12: Indiana Jones and the Kingdom of the Crystal Skull | B12: 39808 | C12: Color | D12: Action | E12: English | F12: USA | G12: PG-13 | H12: Harrison Ford | I12: Steven Spielberg | J12: 11000 | K12: 14959 | L12: 14000 | M12: 5000 | N12: 6.2 | O12: 470 | P12: 122 | Q12: 317011114 | R12: 185000000 | S12: =Q12-R12 -> 132011114 | T12: =IF(R12>0, (Q12-R12)/R12, 0) -> 0.71357359 | U12: =(N12*4) + (T12*0.4) + (M12/10000) -> 25.585429 | V12: =YEAR(B12) -> 2008 | W12: =TEXT(B12, "mmmm") -> dekabr | X12: =TRIM(I12) -> Steven Spielberg | Y12: =UPPER(A12) -> INDİANA JONES AND THE KİNGDOM OF THE CRYSTAL SKULL | Z12: =IF(AND(R12>50000000, S12<0), "Underperformer", IF(AND(R12<10000000, S12>50000000), "Overperformer", "Normal")) -> Normal | AA12: =VLOOKUP(D12, lookups!$A$2:$B$18, 2, FALSE) -> High Budget | AB12: =IF(AND(N12>7, T12>1, U12>70), "Recommended", "Not Recommended") -> Not Recommended | AC12: =IF(N12>=8, "High Buzz / High Score", IF(AND(N12<6, T12<1), "High Buzz Mismatch", "Normal")) -> Normal
A13: The Hunger Games: Catching Fire | B13: 41347 | C13: Color | D13: Adventure | E13: English | F13: USA | G13: PG-13 | H13: Jennifer Lawrence | I13: Francis Lawrence | J13: 34000 | K13: 49355 | L13: 508 | M13: 82000 | N13: 7.6 | O13: 502 | P13: 146 | Q13: 424645577 | R13: 130000000 | S13: =Q13-R13 -> 294645577 | T13: =IF(R13>0, (Q13-R13)/R13, 0) -> 2.2665044 | U13: =(N13*4) + (T13*0.4) + (M13/10000) -> 39.506602 | V13: =YEAR(B13) -> 2013 | W13: =TEXT(B13, "mmmm") -> mart | X13: =TRIM(I13) -> Francis Lawrence | Y13: =UPPER(A13) -> THE HUNGER GAMES: CATCHİNG FİRE | Z13: =IF(AND(R13>50000000, S13<0), "Underperformer", IF(AND(R13<10000000, S13>50000000), "Overperformer", "Normal")) -> Normal | AA13: =VLOOKUP(D13, lookups!$A$2:$B$18, 2, FALSE) -> High Budget | AB13: =IF(AND(N13>7, T13>1, U13>70), "Recommended", "Not Recommended") -> Not Recommended | AC13: =IF(N13>=8, "High Buzz / High Score", IF(AND(N13<6, T13<1), "High Buzz Mismatch", "Normal")) -> Normal
... A2732: Promised Land | B2732: 41253 | C2732: Color | D2732: Drama | E2732: English | F2732: USA | G2732: R | H2732: Matt Damon | I2732: Gus Van Sant | J2732: 13000 | K2732: 14544 | L2732: 835 | M2732: 10000 | N2732: 6.6 | O2732: 242 | P2732: 106 | Q2732: 7556708 | R2732: 15000000 | S2732: =Q2732-R2732 -> -7443292 | T2732: =IF(R2732>0, (Q2732-R2732)/R2732, 0) -> -0.49621947 | U2732: =(N2732*4) + (T2732*0.4) + (M2732/10000) -> 27.201512 | V2732: =YEAR(B2732) -> 2012 | W2732: =TEXT(B2732, "mmmm") -> dekabr | X2732: =TRIM(I2732) -> Gus Van Sant | Y2732: =UPPER(A2732) -> PROMİSED LAND | Z2732: =IF(AND(R2732>50000000, S2732<0), "Underperformer", IF(AND(R2732<10000000, S2732>50000000), "Overperformer", "Normal")) -> Normal | AA2732: =VLOOKUP(D2732, lookups!$A$2:$B$18, 2, FALSE) -> Medium Budget | AB2732: =IF(AND(N2732>7, T2732>1, U2732>70), "Recommended", "Not Recommended") -> Not Recommended | AC2732: =IF(N2732>=8, "High Buzz / High Score", IF(AND(N2732<6, T2732<1), "High Buzz Mismatch", "Normal")) -> Normal
A2733: Dolphins and Whales 3D: Tribes of the Ocean | B2733: 39622 | C2733: Color | D2733: Adventure | E2733: English | F2733: UK | H2733: Charlotte Rampling | I2733: Jean-Jacques Mantello | J2733: 844 | K2733: 844 | L2733: 0 | M2733: 28 | N2733: 6.5 | O2733: 9 | P2733: 42 | Q2733: 7518876 | R2733: 6000000 | S2733: =Q2733-R2733 -> 1518876 | T2733: =IF(R2733>0, (Q2733-R2733)/R2733, 0) -> 0.253146 | U2733: =(N2733*4) + (T2733*0.4) + (M2733/10000) -> 26.104058 | V2733: =YEAR(B2733) -> 2008 | W2733: =TEXT(B2733, "mmmm") -> iyun | X2733: =TRIM(I2733) -> Jean-Jacques Mantello | Y2733: =UPPER(A2733) -> DOLPHİNS AND WHALES 3D: TRİBES OF THE OCEAN | Z2733: =IF(AND(R2733>50000000, S2733<0), "Underperformer", IF(AND(R2733<10000000, S2733>50000000), "Overperformer", "Normal")) -> Normal | AA2733: =VLOOKUP(D2733, lookups!$A$2:$B$18, 2, FALSE) -> High Budget | AB2733: =IF(AND(N2733>7, T2733>1, U2733>70), "Recommended", "Not Recommended") -> Not Recommended | AC2733: =IF(N2733>=8, "High Buzz / High Score", IF(AND(N2733<6, T2733<1), "High Buzz Mismatch", "Normal")) -> Normal
A2734: The Curse of the Jade Scorpion | B2734: 36991 | C2734: Color | D2734: Comedy | E2734: English | F2734: USA | G2734: PG-13 | H2734: Woody Allen | I2734: Woody Allen | J2734: 11000 | K2734: 12534 | L2734: 11000 | M2734: 826 | N2734: 6.8 | O2734: 116 | P2734: 103 | Q2734: 7496522 | R2734: 26000000 | S2734: =Q2734-R2734 -> -18503478 | T2734: =IF(R2734>0, (Q2734-R2734)/R2734, 0) -> -0.71167223 | U2734: =(N2734*4) + (T2734*0.4) + (M2734/10000) -> 26.997931 | V2734: =YEAR(B2734) -> 2001 | W2734: =TEXT(B2734, "mmmm") -> aprel | X2734: =TRIM(I2734) -> Woody Allen | Y2734: =UPPER(A2734) -> THE CURSE OF THE JADE SCORPİON | Z2734: =IF(AND(R2734>50000000, S2734<0), "Underperformer", IF(AND(R2734<10000000, S2734>50000000), "Overperformer", "Normal")) -> Normal | AA2734: =VLOOKUP(D2734, lookups!$A$2:$B$18, 2, FALSE) -> Medium Budget | AB2734: =IF(AND(N2734>7, T2734>1, U2734>70), "Recommended", "Not Recommended") -> Not Recommended | AC2734: =IF(N2734>=8, "High Buzz / High Score", IF(AND(N2734<6, T2734<1), "High Buzz Mismatch", "Normal")) -> Normal
A2735: Martian Child | B2735: 39311 | C2735: Color | D2735: Comedy | E2735: English | F2735: USA | G2735: PG | H2735: Oliver Platt | I2735: Menno Meyjes | J2735: 1000 | K2735: 2495 | L2735: 43 | M2735: 0 | N2735: 6.8 | O2735: 118 | P2735: 106 | Q2735: 7486906 | R2735: 27000000 | S2735: =Q2735-R2735 -> -19513094 | T2735: =IF(R2735>0, (Q2735-R2735)/R2735, 0) -> -0.72270719 | U2735: =(N2735*4) + (T2735*0.4) + (M2735/10000) -> 26.910917 | V2735: =YEAR(B2735) -> 2007 | W2735: =TEXT(B2735, "mmmm") -> avgust | X2735: =TRIM(I2735) -> Menno Meyjes | Y2735: =UPPER(A2735) -> MARTİAN CHİLD | Z2735: =IF(AND(R2735>50000000, S2735<0), "Underperformer", IF(AND(R2735<10000000, S2735>50000000), "Overperformer", "Normal")) -> Normal | AA2735: =VLOOKUP(D2735, lookups!$A$2:$B$18, 2, FALSE) -> Medium Budget | AB2735: =IF(AND(N2735>7, T2735>1, U2735>70), "Recommended", "Not Recommended") -> Not Recommended | AC2735: =IF(N2735>=8, "High Buzz / High Score", IF(AND(N2735<6, T2735<1), "High Buzz Mismatch", "Normal")) -> Normal
A2736: A Good Year | B2736: 38756 | C2736: Color | D2736: Comedy | E2736: English | F2736: USA | G2736: PG-13 | H2736: Archie Panjabi | I2736: Ridley Scott | J2736: 883 | K2736: 3611 | L2736: 0 | M2736: 9000 | N2736: 6.9 | O2736: 147 | P2736: 117 | Q2736: 7458269 | R2736: 35000000 | S2736: =Q2736-R2736 -> -27541731 | T2736: =IF(R2736>0, (Q2736-R2736)/R2736, 0) -> -0.7869066 | U2736: =(N2736*4) + (T2736*0.4) + (M2736/10000) -> 28.185237 | V2736: =YEAR(B2736) -> 2006 | W2736: =TEXT(B2736, "mmmm") -> fevral | X2736: =TRIM(I2736) -> Ridley Scott | Y2736: =UPPER(A2736) -> A GOOD YEAR | Z2736: =IF(AND(R2736>50000000, S2736<0), "Underperformer", IF(AND(R2736<10000000, S2736>50000000), "Overperformer", "Normal")) -> Normal | AA2736: =VLOOKUP(D2736, lookups!$A$2:$B$18, 2, FALSE) -> Medium Budget | AB2736: =IF(AND(N2736>7, T2736>1, U2736>70), "Recommended", "Not Recommended") -> Not Recommended | AC2736: =IF(N2736>=8, "High Buzz / High Score", IF(AND(N2736<6, T2736<1), "High Buzz Mismatch", "Normal")) -> Normal
A2737: Cyrus | B2737: 40389 | C2737: Color | D2737: Comedy | E2737: English | F2737: USA | G2737: R | H2737: Matt Walsh | I2737: Jay Duplass | J2737: 490 | K2737: 1136 | L2737: 157 | M2737: 0 | N2737: 6.3 | O2737: 223 | P2737: 91 | Q2737: 7455447 | R2737: 7000000 | S2737: =Q2737-R2737 -> 455447 | T2737: =IF(R2737>0, (Q2737-R2737)/R2737, 0) -> 0.065063857 | U2737: =(N2737*4) + (T2737*0.4) + (M2737/10000) -> 25.226026 | V2737: =YEAR(B2737) -> 2010 | W2737: =TEXT(B2737, "mmmm") -> iyul | X2737: =TRIM(I2737) -> Jay Duplass | Y2737: =UPPER(A2737) -> CYRUS | Z2737: =IF(AND(R2737>50000000, S2737<0), "Underperformer", IF(AND(R2737<10000000, S2737>50000000), "Overperformer", "Normal")) -> Normal | AA2737: =VLOOKUP(D2737, lookups!$A$2:$B$18, 2, FALSE) -> Medium Budget | AB2737: =IF(AND(N2737>7, T2737>1, U2737>70), "Recommended", "Not Recommended") -> Not Recommended | AC2737: =IF(N2737>=8, "High Buzz / High Score", IF(AND(N2737<6, T2737<1), "High Buzz Mismatch", "Normal")) -> Normal
A2738: Taking Woodstock | B2738: 40127 | C2738: Color | D2738: Comedy | E2738: English | F2738: USA | G2738: R | H2738: Imelda Staunton | I2738: Ang Lee | J2738: 579 | K2738: 1500 | L2738: 0 | M2738: 0 | N2738: 6.7 | O2738: 210 | P2738: 120 | Q2738: 7443007 | R2738: 30000000 | S2738: =Q2738-R2738 -> -22556993 | T2738: =IF(R2738>0, (Q2738-R2738)/R2738, 0) -> -0.75189977 | U2738: =(N2738*4) + (T2738*0.4) + (M2738/10000) -> 26.49924 | V2738: =YEAR(B2738) -> 2009 | W2738: =TEXT(B2738, "mmmm") -> noyabr | X2738: =TRIM(I2738) -> Ang Lee | Y2738: =UPPER(A2738) -> TAKİNG WOODSTOCK | Z2738: =IF(AND(R2738>50000000, S2738<0), "Underperformer", IF(AND(R2738<10000000, S2738>50000000), "Overperformer", "Normal")) -> Normal | AA2738: =VLOOKUP(D2738, lookups!$A$2:$B$18, 2, FALSE) -> Medium Budget | AB2738: =IF(AND(N2738>7, T2738>1, U2738>70), "Recommended", "Not Recommended") -> Not Recommended | AC2738: =IF(N2738>=8, "High Buzz / High Score", IF(AND(N2738<6, T2738<1), "High Buzz Mismatch", "Normal")) -> Normal
A2739: Harley Davidson and the Marlboro Man | B2739: 33494 | C2739: Color | D2739: Action | E2739: English | F2739: USA | G2739: R | H2739: Vanessa Williams | I2739: Simon Wincer | J2739: 1000 | K2739: 3671 | L2739: 23 | M2739: 0 | N2739: 6 | O2739: 30 | P2739: 98 | Q2739: 7434726 | R2739: 23000000 | S2739: =Q2739-R2739 -> -15565274 | T2739: =IF(R2739>0, (Q2739-R2739)/R2739, 0) -> -0.67675104 | U2739: =(N2739*4) + (T2739*0.4) + (M2739/10000) -> 23.7293 | V2739: =YEAR(B2739) -> 1991 | W2739: =TEXT(B2739, "mmmm") -> sentyabr | X2739: =TRIM(I2739) -> Simon Wincer | Y2739: =UPPER(A2739) -> HARLEY DAVİDSON AND THE MARLBORO MAN | Z2739: =IF(AND(R2739>50000000, S2739<0), "Underperformer", IF(AND(R2739<10000000, S2739>50000000), "Overperformer", "Normal")) -> Normal | AA2739: =VLOOKUP(D2739, lookups!$A$2:$B$18, 2, FALSE) -> High Budget | AB2739: =IF(AND(N2739>7, T2739>1, U2739>70), "Recommended", "Not Recommended") -> Not Recommended | AC2739: =IF(N2739>=8, "High Buzz / High Score", IF(AND(N2739<6, T2739<1), "High Buzz Mismatch", "Normal")) -> Normal
A2740: Kids | B2740: 35043 | C2740: Color | D2740: Drama | E2740: English | F2740: USA | H2740: Rosario Dawson | I2740: Larry Clark | J2740: 3000 | K2740: 3310 | L2740: 184 | M2740: 0 | N2740: 7 | O2740: 71 | P2740: 91 | Q2740: 7417210 | R2740: 1500000 | S2740: =Q2740-R2740 -> 5917210 | T2740: =IF(R2740>0, (Q2740-R2740)/R2740, 0) -> 3.9448067 | U2740: =(N2740*4) + (T2740*0.4) + (M2740/10000) -> 29.577923 | V2740: =YEAR(B2740) -> 1995 | W2740: =TEXT(B2740, "mmmm") -> dekabr | X2740: =TRIM(I2740) -> Larry Clark | Y2740: =UPPER(A2740) -> KİDS | Z2740: =IF(AND(R2740>50000000, S2740<0), "Underperformer", IF(AND(R2740<10000000, S2740>50000000), "Overperformer", "Normal")) -> Normal | AA2740: =VLOOKUP(D2740, lookups!$A$2:$B$18, 2, FALSE) -> Medium Budget | AB2740: =IF(AND(N2740>7, T2740>1, U2740>70), "Recommended", "Not Recommended") -> Not Recommended | AC2740: =IF(N2740>=8, "High Buzz / High Score", IF(AND(N2740<6, T2740<1), "High Buzz Mismatch", "Normal")) -> Normal
A2741: Doogal | B2741: 38752 | C2741: Color | D2741: Adventure | E2741: English | F2741: USA | G2741: G | H2741: Jimmy Fallon | I2741: Dave Borthwick | J2741: 787 | K2741: 2185 | L2741: 3 | M2741: 346 | N2741: 2.8 | O2741: 31 | P2741: 77 | Q2741: 7382993 | R2741: 20000000 | S2741: =Q2741-R2741 -> -12617007 | T2741: =IF(R2741>0, (Q2741-R2741)/R2741, 0) -> -0.63085035 | U2741: =(N2741*4) + (T2741*0.4) + (M2741/10000) -> 10.98226 | V2741: =YEAR(B2741) -> 2006 | W2741: =TEXT(B2741, "mmmm") -> fevral | X2741: =TRIM(I2741) -> Dave Borthwick | Y2741: =UPPER(A2741) -> DOOGAL | Z2741: =IF(AND(R2741>50000000, S2741<0), "Underperformer", IF(AND(R2741<10000000, S2741>50000000), "Overperformer", "Normal")) -> Normal | AA2741: =VLOOKUP(D2741, lookups!$A$2:$B$18, 2, FALSE) -> High Budget | AB2741: =IF(AND(N2741>7, T2741>1, U2741>70), "Recommended", "Not Recommended") -> Not Recommended | AC2741: =IF(N2741>=8, "High Buzz / High Score", IF(AND(N2741<6, T2741<1), "High Buzz Mismatch", "Normal")) -> High Buzz Mismatch
A2742: Witchboard | B2742: 31663 | C2742: Color | D2742: Horror | E2742: English | F2742: UK | G2742: R | H2742: Kathleen Wilhoite | I2742: Kevin Tenney | J2742: 265 | K2742: 901 | L2742: 85 | M2742: 0 | N2742: 5.7 | O2742: 65 | P2742: 98 | Q2742: 7369373 | R2742: 2000000 | S2742: =Q2742-R2742 -> 5369373 | T2742: =IF(R2742>0, (Q2742-R2742)/R2742, 0) -> 2.6846865 | U2742: =(N2742*4) + (T2742*0.4) + (M2742/10000) -> 23.873875 | V2742: =YEAR(B2742) -> 1986 | W2742: =TEXT(B2742, "mmmm") -> sentyabr | X2742: =TRIM(I2742) -> Kevin Tenney | Y2742: =UPPER(A2742) -> WİTCHBOARD | Z2742: =IF(AND(R2742>50000000, S2742<0), "Underperformer", IF(AND(R2742<10000000, S2742>50000000), "Overperformer", "Normal")) -> Normal | AA2742: =VLOOKUP(D2742, lookups!$A$2:$B$18, 2, FALSE) -> Low Budget | AB2742: =IF(AND(N2742>7, T2742>1, U2742>70), "Recommended", "Not Recommended") -> Not Recommended | AC2742: =IF(N2742>=8, "High Buzz / High Score", IF(AND(N2742<6, T2742<1), "High Buzz Mismatch", "Normal")) -> Normal
A2743: The Squid and the Whale | B2743: 38471 | C2743: Color | D2743: Comedy | E2743: English | F2743: USA | G2743: R | H2743: William Baldwin | I2743: Noah Baumbach | J2743: 436 | K2743: 479 | L2743: 387 | M2743: 0 | N2743: 7.4 | O2743: 110 | P2743: 88 | Q2743: 7362100 | R2743: 1500000 | S2743: =Q2743-R2743 -> 5862100 | T2743: =IF(R2743>0, (Q2743-R2743)/R2743, 0) -> 3.9080667 | U2743: =(N2743*4) + (T2743*0.4) + (M2743/10000) -> 31.163227 | V2743: =YEAR(B2743) -> 2005 | W2743: =TEXT(B2743, "mmmm") -> aprel | X2743: =TRIM(I2743) -> Noah Baumbach | Y2743: =UPPER(A2743) -> THE SQUİD AND THE WHALE | Z2743: =IF(AND(R2743>50000000, S2743<0), "Underperformer", IF(AND(R2743<10000000, S2743>50000000), "Overperformer", "Normal")) -> Normal | AA2743: =VLOOKUP(D2743, lookups!$A$2:$B$18, 2, FALSE) -> Medium Budget | AB2743: =IF(AND(N2743>7, T2743>1, U2743>70), "Recommended", "Not Recommended") -> Not Recommended | AC2743: =IF(N2743>=8, "High Buzz / High Score", IF(AND(N2743<6, T2743<1), "High Buzz Mismatch", "Normal")) -> Normal
A2744: Outside Providence | B2744: 36495 | C2744: Color | D2744: Comedy | E2744: English | F2744: USA | G2744: R | H2744: Jonathan Brandis | I2744: Michael Corrente | J2744: 761 | K2744: 2018 | L2744: 30 | M2744: 0 | N2744: 6.4 | O2744: 72 | P2744: 96 | Q2744: 7292175 | R2744: 7000000 | S2744: =Q2744-R2744 -> 292175 | T2744: =IF(R2744>0, (Q2744-R2744)/R2744, 0) -> 0.041739286 | U2744: =(N2744*4) + (T2744*0.4) + (M2744/10000) -> 25.616696 | V2744: =YEAR(B2744) -> 1999 | W2744: =TEXT(B2744, "mmmm") -> dekabr | X2744: =TRIM(I2744) -> Michael Corrente | Y2744: =UPPER(A2744) -> OUTSİDE PROVİDENCE | Z2744: =IF(AND(R2744>50000000, S2744<0), "Underperformer", IF(AND(R2744<10000000, S2744>50000000), "Overperformer", "Normal")) -> Normal | AA2744: =VLOOKUP(D2744, lookups!$A$2:$B$18, 2, FALSE) -> Medium Budget | AB2744: =IF(AND(N2744>7, T2744>1, U2744>70), "Recommended", "Not Recommended") -> Not Recommended | AC2744: =IF(N2744>=8, "High Buzz / High Score", IF(AND(N2744<6, T2744<1), "High Buzz Mismatch", "Normal")) -> Normal
A2745: Phantasm II | B2745: 32228 | C2745: Color | D2745: Action | E2745: English | F2745: USA | G2745: R | H2745: Angus Scrimm | I2745: Don Coscarelli | J2745: 674 | K2745: 1395 | L2745: 152 | M2745: 812 | N2745: 6.5 | O2745: 81 | P2745: 97 | Q2745: 7282851 | R2745: 3000000 | S2745: =Q2745-R2745 -> 4282851 | T2745: =IF(R2745>0, (Q2745-R2745)/R2745, 0) -> 1.427617 | U2745: =(N2745*4) + (T2745*0.4) + (M2745/10000) -> 26.652247 | V2745: =YEAR(B2745) -> 1988 | W2745: =TEXT(B2745, "mmmm") -> mart | X2745: =TRIM(I2745) -> Don Coscarelli | Y2745: =UPPER(A2745) -> PHANTASM II | Z2745: =IF(AND(R2745>50000000, S2745<0), "Underperformer", IF(AND(R2745<10000000, S2745>50000000), "Overperformer", "Normal")) -> Normal | AA2745: =VLOOKUP(D2745, lookups!$A$2:$B$18, 2, FALSE) -> High Budget | AB2745: =IF(AND(N2745>7, T2745>1, U2745>70), "Recommended", "Not Recommended") -> Not Recommended | AC2745: =IF(N2745>=8, "High Buzz / High Score", IF(AND(N2745<6, T2745<1), "High Buzz Mismatch", "Normal")) -> Normal
A2746: Machete Kills | B2746: 41474 | C2746: Color | D2746: Action | E2746: English | F2746: Russia | G2746: R | H2746: Alexa PenaVega | I2746: Robert Rodriguez | J2746: 2000 | K2746: 2848 | L2746: 0 | M2746: 48000 | N2746: 5.6 | O2746: 260 | P2746: 107 | Q2746: 7268659 | R2746: 20000000 | S2746: =Q2746-R2746 -> -12731341 | T2746: =IF(R2746>0, (Q2746-R2746)/R2746, 0) -> -0.63656705 | U2746: =(N2746*4) + (T2746*0.4) + (M2746/10000) -> 26.945373 | V2746: =YEAR(B2746) -> 2013 | W2746: =TEXT(B2746, "mmmm") -> iyul | X2746: =TRIM(I2746) -> Robert Rodriguez | Y2746: =UPPER(A2746) -> MACHETE KİLLS | Z2746: =IF(AND(R2746>50000000, S2746<0), "Underperformer", IF(AND(R2746<10000000, S2746>50000000), "Overperformer", "Normal")) -> Normal | AA2746: =VLOOKUP(D2746, lookups!$A$2:$B$18, 2, FALSE) -> High Budget | AB2746: =IF(AND(N2746>7, T2746>1, U2746>70), "Recommended", "Not Recommended") -> Not Recommended | AC2746: =IF(N2746>=8, "High Buzz / High Score", IF(AND(N2746<6, T2746<1), "High Buzz Mismatch", "Normal")) -> High Buzz Mismatch
A2747: Run Lola Run | B2747: 35893 | C2747: Black and White | D2747: Crime | E2747: German | F2747: Germany | G2747: R | H2747: Moritz Bleibtreu | I2747: Tom Tykwer | J2747: 486 | K2747: 623 | L2747: 670 | M2747: 0 | N2747: 7.8 | O2747: 181 | P2747: 81 | Q2747: 7267324 | R2747: 3500000 | S2747: =Q2747-R2747 -> 3767324 | T2747: =IF(R2747>0, (Q2747-R2747)/R2747, 0) -> 1.0763783 | U2747: =(N2747*4) + (T2747*0.4) + (M2747/10000) -> 31.630551 | V2747: =YEAR(B2747) -> 1998 | W2747: =TEXT(B2747, "mmmm") -> aprel | X2747: =TRIM(I2747) -> Tom Tykwer | Y2747: =UPPER(A2747) -> RUN LOLA RUN | Z2747: =IF(AND(R2747>50000000, S2747<0), "Underperformer", IF(AND(R2747<10000000, S2747>50000000), "Overperformer", "Normal")) -> Normal | AA2747: =VLOOKUP(D2747, lookups!$A$2:$B$18, 2, FALSE) -> Medium Budget | AB2747: =IF(AND(N2747>7, T2747>1, U2747>70), "Recommended", "Not Recommended") -> Not Recommended | AC2747: =IF(N2747>=8, "High Buzz / High Score", IF(AND(N2747<6, T2747<1), "High Buzz Mismatch", "Normal")) -> Normal
A2748: Big Trouble | B2748: 37372 | C2748: Color | D2748: Comedy | E2748: English | F2748: USA | G2748: PG-13 | H2748: Zooey Deschanel | I2748: Barry Sonnenfeld | J2748: 11000 | K2748: 13917 | L2748: 188 | M2748: 892 | N2748: 6.5 | O2748: 87 | P2748: 74 | Q2748: 7262288 | R2748: 40000000 | S2748: =Q2748-R2748 -> -32737712 | T2748: =IF(R2748>0, (Q2748-R2748)/R2748, 0) -> -0.8184428 | U2748: =(N2748*4) + (T2748*0.4) + (M2748/10000) -> 25.761823 | V2748: =YEAR(B2748) -> 2002 | W2748: =TEXT(B2748, "mmmm") -> aprel | X2748: =TRIM(I2748) -> Barry Sonnenfeld | Y2748: =UPPER(A2748) -> BİG TROUBLE | Z2748: =IF(AND(R2748>50000000, S2748<0), "Underperformer", IF(AND(R2748<10000000, S2748>50000000), "Overperformer", "Normal")) -> Normal | AA2748: =VLOOKUP(D2748, lookups!$A$2:$B$18, 2, FALSE) -> Medium Budget | AB2748: =IF(AND(N2748>7, T2748>1, U2748>70), "Recommended", "Not Recommended") -> Not Recommended | AC2748: =IF(N2748>=8, "High Buzz / High Score", IF(AND(N2748<6, T2748<1), "High Buzz Mismatch", "Normal")) -> Normal
A2749: All the King's Men | B2749: 39041 | C2749: Black and White | D2749: Drama | E2749: English | F2749: Germany | G2749: PG-13 | H2749: Kate Winslet | I2749: Steven Zaillian | J2749: 14000 | K2749: 27614 | L2749: 234 | M2749: 0 | N2749: 6.2 | O2749: 127 | P2749: 128 | Q2749: 7221458 | R2749: 55000000 | S2749: =Q2749-R2749 -> -47778542 | T2749: =IF(R2749>0, (Q2749-R2749)/R2749, 0) -> -0.86870076 | U2749: =(N2749*4) + (T2749*0.4) + (M2749/10000) -> 24.45252 | V2749: =YEAR(B2749) -> 2006 | W2749: =TEXT(B2749, "mmmm") -> noyabr | X2749: =TRIM(I2749) -> Steven Zaillian | Y2749: =UPPER(A2749) -> ALL THE KİNG'S MEN | Z2749: =IF(AND(R2749>50000000, S2749<0), "Underperformer", IF(AND(R2749<10000000, S2749>50000000), "Overperformer", "Normal")) -> Underperformer | AA2749: =VLOOKUP(D2749, lookups!$A$2:$B$18, 2, FALSE) -> Medium Budget | AB2749: =IF(AND(N2749>7, T2749>1, U2749>70), "Recommended", "Not Recommended") -> Not Recommended | AC2749: =IF(N2749>=8, "High Buzz / High Score", IF(AND(N2749<6, T2749<1), "High Buzz Mismatch", "Normal")) -> Normal
A2750: Mulholland Drive | B2750: 37192 | C2750: Color | D2750: Drama | E2750: English | F2750: France | G2750: R | H2750: Naomi Watts | I2750: David Lynch | J2750: 6000 | K2750: 8484 | L2750: 0 | M2750: 16000 | N2750: 8 | O2750: 252 | P2750: 147 | Q2750: 7219578 | R2750: 15000000 | S2750: =Q2750-R2750 -> -7780422 | T2750: =IF(R2750>0, (Q2750-R2750)/R2750, 0) -> -0.5186948 | U2750: =(N2750*4) + (T2750*0.4) + (M2750/10000) -> 33.392522 | V2750: =YEAR(B2750) -> 2001 | W2750: =TEXT(B2750, "mmmm") -> oktyabr | X2750: =TRIM(I2750) -> David Lynch | Y2750: =UPPER(A2750) -> MULHOLLAND DRİVE | Z2750: =IF(AND(R2750>50000000, S2750<0), "Underperformer", IF(AND(R2750<10000000, S2750>50000000), "Overperformer", "Normal")) -> Normal | AA2750: =VLOOKUP(D2750, lookups!$A$2:$B$18, 2, FALSE) -> Medium Budget | AB2750: =IF(AND(N2750>7, T2750>1, U2750>70), "Recommended", "Not Recommended") -> Not Recommended | AC2750: =IF(N2750>=8, "High Buzz / High Score", IF(AND(N2750<6, T2750<1), "High Buzz Mismatch", "Normal")) -> High Buzz / High Score
A2751: The Big Year | B2751: 40563 | C2751: Color | D2751: Comedy | E2751: English | F2751: USA | G2751: PG | H2751: Joel McHale | I2751: David Frankel | J2751: 734 | K2751: 2085 | L2751: 64 | M2751: 11000 | N2751: 6.2 | O2751: 108 | P2751: 100 | Q2751: 7204138 | R2751: 41000000 | S2751: =Q2751-R2751 -> -33795862 | T2751: =IF(R2751>0, (Q2751-R2751)/R2751, 0) -> -0.82428932 | U2751: =(N2751*4) + (T2751*0.4) + (M2751/10000) -> 25.570284 | V2751: =YEAR(B2751) -> 2011 | W2751: =TEXT(B2751, "mmmm") -> yanvar | X2751: =TRIM(I2751) -> David Frankel | Y2751: =UPPER(A2751) -> THE BİG YEAR | Z2751: =IF(AND(R2751>50000000, S2751<0), "Underperformer", IF(AND(R2751<10000000, S2751>50000000), "Overperformer", "Normal")) -> Normal | AA2751: =VLOOKUP(D2751, lookups!$A$2:$B$18, 2, FALSE) -> Medium Budget | AB2751: =IF(AND(N2751>7, T2751>1, U2751>70), "Recommended", "Not Recommended") -> Not Recommended | AC2751: =IF(N2751>=8, "High Buzz / High Score", IF(AND(N2751<6, T2751<1), "High Buzz Mismatch", "Normal")) -> Normal
A2752: The Green Inferno | B2752: 41292 | C2752: Color | D2752: Adventure | E2752: English | F2752: USA | G2752: R | H2752: Daryl Sabara | I2752: Eli Roth | J2752: 640 | K2752: 2082 | L2752: 0 | M2752: 12000 | N2752: 5.4 | O2752: 285 | P2752: 100 | Q2752: 7186670 | R2752: 6000000 | S2752: =Q2752-R2752 -> 1186670 | T2752: =IF(R2752>0, (Q2752-R2752)/R2752, 0) -> 0.19777833 | U2752: =(N2752*4) + (T2752*0.4) + (M2752/10000) -> 22.879111 | V2752: =YEAR(B2752) -> 2013 | W2752: =TEXT(B2752, "mmmm") -> yanvar | X2752: =TRIM(I2752) -> Eli Roth | Y2752: =UPPER(A2752) -> THE GREEN INFERNO | Z2752: =IF(AND(R2752>50000000, S2752<0), "Underperformer", IF(AND(R2752<10000000, S2752>50000000), "Overperformer", "Normal")) -> Normal | AA2752: =VLOOKUP(D2752, lookups!$A$2:$B$18, 2, FALSE) -> High Budget | AB2752: =IF(AND(N2752>7, T2752>1, U2752>70), "Recommended", "Not Recommended") -> Not Recommended | AC2752: =IF(N2752>=8, "High Buzz / High Score", IF(AND(N2752<6, T2752<1), "High Buzz Mismatch", "Normal")) -> High Buzz Mismatch
... A2797: Maria Full of Grace | B2797: 38215 | C2797: Color | D2797: Crime | E2797: Spanish | F2797: Colombia | G2797: R | H2797: Catalina Sandino Moreno | I2797: Joshua Marston | J2797: 280 | K2797: 308 | L2797: 13 | M2797: 0 | N2797: 7.5 | O2797: 155 | P2797: 101 | Q2797: 6517198 | R2797: 3000000 | S2797: =Q2797-R2797 -> 3517198 | T2797: =IF(R2797>0, (Q2797-R2797)/R2797, 0) -> 1.1723993 | U2797: =(N2797*4) + (T2797*0.4) + (M2797/10000) -> 30.46896 | V2797: =YEAR(B2797) -> 2004 | W2797: =TEXT(B2797, "mmmm") -> avgust | X2797: =TRIM(I2797) -> Joshua Marston | Y2797: =UPPER(A2797) -> MARİA FULL OF GRACE | Z2797: =IF(AND(R2797>50000000, S2797<0), "Underperformer", IF(AND(R2797<10000000, S2797>50000000), "Overperformer", "Normal")) -> Normal | AA2797: =VLOOKUP(D2797, lookups!$A$2:$B$18, 2, FALSE) -> Medium Budget | AB2797: =IF(AND(N2797>7, T2797>1, U2797>70), "Recommended", "Not Recommended") -> Not Recommended | AC2797: =IF(N2797>=8, "High Buzz / High Score", IF(AND(N2797<6, T2797<1), "High Buzz Mismatch", "Normal")) -> Normal
A2798: Baahubali: The Beginning | B2798: 42182 | C2798: Color | D2798: Action | E2798: Telugu | F2798: India | H2798: Tamannaah Bhatia | I2798: S.S. Rajamouli | J2798: 218 | K2798: 554 | L2798: 50 | M2798: 21000 | N2798: 8.4 | O2798: 44 | P2798: 159 | Q2798: 6498000 | R2798: 18026148 | S2798: =Q2798-R2798 -> -11528148 | T2798: =IF(R2798>0, (Q2798-R2798)/R2798, 0) -> -0.63952365 | U2798: =(N2798*4) + (T2798*0.4) + (M2798/10000) -> 35.444191 | V2798: =YEAR(B2798) -> 2015 | W2798: =TEXT(B2798, "mmmm") -> iyun | X2798: =TRIM(I2798) -> S.S. Rajamouli | Y2798: =UPPER(A2798) -> BAAHUBALİ: THE BEGİNNİNG | Z2798: =IF(AND(R2798>50000000, S2798<0), "Underperformer", IF(AND(R2798<10000000, S2798>50000000), "Overperformer", "Normal")) -> Normal | AA2798: =VLOOKUP(D2798, lookups!$A$2:$B$18, 2, FALSE) -> High Budget | AB2798: =IF(AND(N2798>7, T2798>1, U2798>70), "Recommended", "Not Recommended") -> Not Recommended | AC2798: =IF(N2798>=8, "High Buzz / High Score", IF(AND(N2798<6, T2798<1), "High Buzz Mismatch", "Normal")) -> High Buzz / High Score
A2799: Teacher's Pet | B2799: 38101 | C2799: Color | D2799: Animation | E2799: English | F2799: USA | G2799: PG | H2799: Nathan Lane | I2799: Timothy BjÃ¶rklund | J2799: 886 | K2799: 5139 | L2799: 0 | M2799: 49 | N2799: 5.8 | O2799: 33 | P2799: 74 | Q2799: 6491350 | R2799: 10000000 | S2799: =Q2799-R2799 -> -3508650 | T2799: =IF(R2799>0, (Q2799-R2799)/R2799, 0) -> -0.350865 | U2799: =(N2799*4) + (T2799*0.4) + (M2799/10000) -> 23.064554 | V2799: =YEAR(B2799) -> 2004 | W2799: =TEXT(B2799, "mmmm") -> aprel | X2799: =TRIM(I2799) -> Timothy BjÃ¶rklund | Y2799: =UPPER(A2799) -> TEACHER'S PET | Z2799: =IF(AND(R2799>50000000, S2799<0), "Underperformer", IF(AND(R2799<10000000, S2799>50000000), "Overperformer", "Normal")) -> Normal | AA2799: =VLOOKUP(D2799, lookups!$A$2:$B$18, 2, FALSE) -> High Budget | AB2799: =IF(AND(N2799>7, T2799>1, U2799>70), "Recommended", "Not Recommended") -> Not Recommended | AC2799: =IF(N2799>=8, "High Buzz / High Score", IF(AND(N2799<6, T2799<1), "High Buzz Mismatch", "Normal")) -> High Buzz Mismatch
A2800: Switchback | B2800: 35640 | C2800: Color | D2800: Crime | E2800: English | F2800: USA | G2800: R | H2800: Gregory Scott Cummins | I2800: Jeb Stuart | J2800: 37 | K2800: 74 | L2800: 11 | M2800: 389 | N2800: 6.4 | O2800: 38 | P2800: 118 | Q2800: 6482195 | R2800: 37000000 | S2800: =Q2800-R2800 -> -30517805 | T2800: =IF(R2800>0, (Q2800-R2800)/R2800, 0) -> -0.82480554 | U2800: =(N2800*4) + (T2800*0.4) + (M2800/10000) -> 25.308978 | V2800: =YEAR(B2800) -> 1997 | W2800: =TEXT(B2800, "mmmm") -> iyul | X2800: =TRIM(I2800) -> Jeb Stuart | Y2800: =UPPER(A2800) -> SWİTCHBACK | Z2800: =IF(AND(R2800>50000000, S2800<0), "Underperformer", IF(AND(R2800<10000000, S2800>50000000), "Overperformer", "Normal")) -> Normal | AA2800: =VLOOKUP(D2800, lookups!$A$2:$B$18, 2, FALSE) -> Medium Budget | AB2800: =IF(AND(N2800>7, T2800>1, U2800>70), "Recommended", "Not Recommended") -> Not Recommended | AC2800: =IF(N2800>=8, "High Buzz / High Score", IF(AND(N2800<6, T2800<1), "High Buzz Mismatch", "Normal")) -> Normal
A2801: The Big Bounce | B2801: 38234 | C2801: Color | D2801: Comedy | E2801: English | F2801: USA | G2801: PG-13 | H2801: Morgan Freeman | I2801: George Armitage | J2801: 11000 | K2801: 11972 | L2801: 5 | M2801: 288 | N2801: 4.9 | O2801: 75 | P2801: 88 | Q2801: 6471394 | R2801: 50000000 | S2801: =Q2801-R2801 -> -43528606 | T2801: =IF(R2801>0, (Q2801-R2801)/R2801, 0) -> -0.87057212 | U2801: =(N2801*4) + (T2801*0.4) + (M2801/10000) -> 19.280571 | V2801: =YEAR(B2801) -> 2004 | W2801: =TEXT(B2801, "mmmm") -> sentyabr | X2801: =TRIM(I2801) -> George Armitage | Y2801: =UPPER(A2801) -> THE BİG BOUNCE | Z2801: =IF(AND(R2801>50000000, S2801<0), "Underperformer", IF(AND(R2801<10000000, S2801>50000000), "Overperformer", "Normal")) -> Normal | AA2801: =VLOOKUP(D2801, lookups!$A$2:$B$18, 2, FALSE) -> Medium Budget | AB2801: =IF(AND(N2801>7, T2801>1, U2801>70), "Recommended", "Not Recommended") -> Not Recommended | AC2801: =IF(N2801>=8, "High Buzz / High Score", IF(AND(N2801<6, T2801<1), "High Buzz Mismatch", "Normal")) -> High Buzz Mismatch
A2802: Warriors of Virtue | B2802: 35431 | C2802: Color | D2802: Action | E2802: English | F2802: USA | G2802: PG | H2802: Marley Shelton | I2802: Ronny Yu | J2802: 690 | K2802: 1993 | L2802: 31 | M2802: 0 | N2802: 4.6 | O2802: 24 | P2802: 101 | Q2802: 6448817 | R2802: 35000000 | S2802: =Q2802-R2802 -> -28551183 | T2802: =IF(R2802>0, (Q2802-R2802)/R2802, 0) -> -0.81574809 | U2802: =(N2802*4) + (T2802*0.4) + (M2802/10000) -> 18.073701 | V2802: =YEAR(B2802) -> 1997 | W2802: =TEXT(B2802, "mmmm") -> yanvar | X2802: =TRIM(I2802) -> Ronny Yu | Y2802: =UPPER(A2802) -> WARRİORS OF VİRTUE | Z2802: =IF(AND(R2802>50000000, S2802<0), "Underperformer", IF(AND(R2802<10000000, S2802>50000000), "Overperformer", "Normal")) -> Normal | AA2802: =VLOOKUP(D2802, lookups!$A$2:$B$18, 2, FALSE) -> High Budget | AB2802: =IF(AND(N2802>7, T2802>1, U2802>70), "Recommended", "Not Recommended") -> Not Recommended | AC2802: =IF(N2802>=8, "High Buzz / High Score", IF(AND(N2802<6, T2802<1), "High Buzz Mismatch", "Normal")) -> High Buzz Mismatch
...

Sheet lookups
A1: Genre | B1: Genre Category
A2: Action | B2: High Budget
A3: Adventure | B3: High Budget
A4: Animation | B4: High Budget
A5: Biography | B5: Medium Budget
A6: Comedy | B6: Medium Budget
A7: Crime | B7: Medium Budget
A8: Documentary | B8: Low Budget
A9: Drama | B9: Medium Budget
A10: Family | B10: Low Budget
A11: Fantasy | B11: Low Budget
A12: Horror | B12: Low Budget
... A18: Western | B18: Low Budget

Sheet pivot_tables
A1: Row Labels | B1: Average of IMDb Score (1-10) | C1: Average of Success Score | E1: Row Labels | F1: Count of Title | M1: Row Labels | N1: Average of IMDb Score (1-10) | O1: Average of Gross Revenue | P1: Average of Duration (min) | R1: Sum of Gross Revenue | S1: Sum of Profit | T1: Average of IMDb Score (1-10) | U1: Count of Movie Title(UPPER)
A2: Horror | B2: 5.7915584 | C2: 52.240882 | E2: Christopher Nolan | F2: 8 | M2: Black and White | N2: 7.1085938 | O2: 32888710 | P2: 115.55469 | R2: 185670019307 | S2: 19978735058 | T2: 6.4628143 | U2: 3738
A3: Biography | B3: 7.1502439 | C3: 35.476621 | E3: Quentin Tarantino | F3: 8 | M3: Color | N3: 6.4399169 | O3: 50266001 | P3: 109.55112
A4: Musical | B4: 6.75 | C4: 34.785478 | E4: Hayao Miyazaki | F4: 4 | M4: Grand Total | N4: 6.4628143 | O4: 49670952 | P4: 109.75676
A5: Family | B5: 6.5 | C5: 32.405196 | E5: Grand Total | F5: 20
A6: Western | B6: 6.7666667 | C6: 29.894958 | I6: Row Labels | J6: Sum of Budget | K6: Sum of Gross Revenue | L6: Average of Budget | R6: Row Labels | S6: Max of ROI(%)
A7: Documentary | B7: 6.9522727 | C7: 29.7862 | E7: Row Labels | F7: Count of Title | G7: Average of IMDb Score (1-10) | I7: Australia | J7: 1343505523 | K7: 1506979847 | L7: 34448860 | R7: Paranormal Activity | S7: 7193.4855
A8: Animation | B8: 6.7622222 | C8: 29.137409 | E8: Christopher Nolan | F8: 8 | G8: 8.4125 | I8: Canada | J8: 1364990000 | K8: 1575353290 | L8: 21666508 | R8: Tarnation | S8: 2714.6606
A9: Crime | B9: 6.9376984 | C9: 28.98995 | E9: Hayao Miyazaki | F9: 4 | G9: 8.225 | I9: France | J9: 3613494500 | K9: 1885953657 | L9: 34414233 | R9: The Blair Witch Project | S9: 2341.1686
A10: Drama | B10: 6.8238872 | C10: 28.944132 | E10: Quentin Tarantino | F10: 8 | G10: 8.2 | I10: Germany | J10: 2853400000 | K10: 2291916683 | L10: 36118987 | R10: The Brothers McMullen | S10: 408.864
A11: Adventure | B11: 6.5568681 | C11: 28.068889 | E11: Milos Forman | F11: 3 | G11: 8.1333333 | I11: Hungary | J11: 2520000000 | K11: 23375191 | L11: 1260000000 | R11: The Texas Chain Saw Massacre | S11: 368.42729
A12: Mystery | B12: 6.5869565 | C12: 27.964705 | E12: Pete Docter | F12: 3 | G12: 8.2333333 | I12: India | J12: 1576543748 | K12: 40578143 | L12: 1.1261027e+08 | R12: El Mariachi | S12: 290.56
A13: Fantasy | B13: 6.2342857 | C13: 27.949145 | E13: Sergio Leone | F13: 3 | G13: 8.4333333 | I13: Japan | J13: 6913919898 | K13: 356915645 | L13: 4.0670117e+08 | R13: The Gallows | S13: 226.57819
A14: Sci-Fi | B14: 6.5875 | C14: 27.194027 | E14: Grand Total | F14: 29 | G14: 8.2827586 | I14: South Korea | J14: 16528900000 | K14: 21516040 | L14: 2066112500 | R14: Super Size Me | S14: 176.37489
A15: Action | B15: 6.2802661 | C15: 26.527607 | I15: UK | J15: 8616094127 | K15: 9842363547 | L15: 28157170 | R15: Halloween | S15: 155.66667
A16: Romance | B16: 6.1333333 | C16: 26.189509 | E16: Row Labels | F16: Average of Gross Revenue | G16: Sum of Cast FB Likes | I16: USA | J16: 114973672678 | K16: 165884530622 | L16: 38934532 | R16: American Graffiti | S16: 147.00515
A17: Comedy | B17: 6.1699411 | C17: 26.0894 | E17: Anchorman: The Legend of Ron Burgundy | F17: 84136909 | G17: 656730 | I17: Grand Total | J17: 160304520474 | K17: 183429482665 | L17: 44702878 | R17: Grand Total | S17: 7193.4855
A18: Thriller | B18: 5.3 | C18: 22.152338 | E18: Armored | F18: 15988876 | G18: 137712
A19: Grand Total | B19: 6.4628143 | C19: 28.81162 | E19: Evan Almighty | F19: 100289690 | G19: 108016
E20: Firewall | F20: 48745150 | G20: 101383
A21: Horror , Biography və Musical janrları ən yüksək orta Success Score-a malikdir | E21: Hardflip | F21: 96734 | G21: 263584
E22: Hostage | F22: 34636443 | G22: 103354
E23: Quarantine | F23: 31691811 | G23: 140268
E24: The Amityville Horror | F24: 64255243 | G24: 120797
E25: The Dark Knight Rises | F25: 448130642 | G25: 106759
E26: The Final Destination | F26: 66466372 | G26: 303717
E27: Grand Total | F27: 89443787 | G27: 2042320
E44: Row Labels | F44: Sum of Movie FB Likes | G44: Average of IMDb Score (1-10) | H44: Sum of Gross Revenue
E45: THE REVENANT | F45: 190000 | G45: 8.1 | H45: 183635922
E46: THE MARTİAN | F46: 153000 | G46: 8.1 | H46: 228430993
E47: THE IMİTATİON GAME | F47: 165000 | G47: 8.1 | H47: 91121452
E48: THE HOBBİT: AN UNEXPECTED JOURNEY | F48: 166000 | G48: 7.9 | H48: 303001229
E49: THE DARK KNİGHT RİSES | F49: 164000 | G49: 8.4 | H49: 448130642
E50: MAD MAX: FURY ROAD | F50: 191000 | G50: 8.1 | H50: 153629485
E51: JURASSİC WORLD | F51: 150000 | G51: 7 | H51: 652177271
E52: INTERSTELLAR | F52: 349000 | G52: 8.6 | H52: 187991439
E53: INCEPTİON | F53: 175000 | G53: 8.8 | H53: 292568851
E54: DJANGO UNCHAİNED | F54: 199000 | G54: 8.5 | H54: 162804648
E55: Grand Total | F55: 1902000 | G55: 8.16 | H55: 2703491932

Sheet dashboard
A1: "IMDB Movies & Directors Analytics Dashboard"
B2: Total Revenue | E2: Total Profit | H2: Average IMDb Score | K2: Total Movies
B3: =GETPIVOTDATA("Sum of Gross Revenue",pivot_tables!$R$1) -> 185670019307 | E3: =GETPIVOTDATA("Sum of Profit",pivot_tables!$R$1) -> 19978735058 | H3: =GETPIVOTDATA("Average of IMDb Score (1-10)",pivot_tables!$R$1) -> 6.4628143 | K3: =GETPIVOTDATA("Count of Movie Title(UPPER)",pivot_tables!$R$1) -> 3738
